Workbook

Sheet Main Page
A1: SL | B1: Category (FG) | D1: Item Description | E1: Production Plan | F1: ERP Production Done | G1: Physical Production Done | H1: ERP Pending | I1: Production Due | K1: Daily Target
A2: Exhaust Fan
A3: 1 | B3: EF0801OW/EF0801OW | C3: Ex-08 Copper | D3: 08 Inch Fresh Air Exhaust Fan Off White | E3: 2700 | F3: {=_xlfn.XLOOKUP(B3:B6,'ERP Entry FG'!E:E,'ERP Entry FG'!L:L,0)} -> 2690 | G3: 2522 | H3: =G3-F3 -> -168 | I3: =E3-G3 -> 178 | K3: 200
A4: 2 | B4: EF1001OW/EF1001OW | C4: Ex-10 Copper | D4: 10 Inch Fresh Air Exhaust Fan Off White | E4: 2200 | F4: 1554 | G4: 870 | H4: =G4-F4 -> -684 | I4: =E4-G4 -> 1330 | K4: 1000
A5: 3 | B5: EF1001AF | C5: Ex-10 Aluminium | D5: Aero Flow 10`` Exhaust Fan | E5: 8300 | F5: 3078 | G5: 3048 | H5: =G5-F5 -> -30 | I5: =E5-G5 -> 5252 | K5: 1000
A6: 4 | B6: EF0801AF | C6: Ex-08 Aluminium | D6: Aero Flow 8`` Exhaust Fan | E6: 2600 | F6: 2626 | G6: 2626 | H6: =G6-F6 -> 0 | I6: =E6-G6 -> -26 | K6: 1000
A8: Capacitor
A9: 1 | B9: CFCP001 | C9: Capacitor 2.5 | D9: Ceiling Fan Capacitor 2.5 uf | E9: 75000 | F9: {=_xlfn.XLOOKUP(B9:B10,'ERP Entry FG'!E:E,'ERP Entry FG'!L:L,0)} -> 70128 | G9: 54000 | H9: =G9-F9 -> -16128 | I9: =E9-G9 -> 21000 | K9: 7000
A10: 2 | B10: CFCP002 | C10: Capacitor 3.5 | D10: Ceiling Fan Capacitor 3.5 uf | E10: 50000 | F10: 79872 | G10: 27360 | H10: =G10-F10 -> -52512 | I10: =E10-G10 -> 22640 | K10: 7000
A12: Ceiling Fan | E12: =SUM(E13:E20) -> 45000
A13: 1 | B13: CF5601/CF5601IV | C13: CF 5601 | D13: 56 Inch Premium Ceiling Fan - Ivory | E13: 30000 | F13: {=_xlfn.XLOOKUP(B13:B20,'ERP Entry FG'!E:E,'ERP Entry FG'!L:L,0)} -> 30786 | I13: =E13-G13 -> 30000 | K13: 1000
A14: 2 | B14: CF5602/CF5602IV | C14: CF 5602 | D14: 56 Inch Speed King Ceiling Fan - Ivory | F14: 0 | I14: =E14-G14 -> 0
A15: 3 | B15: CF5603/CF5603IV | C15: CF 5603 | D15: 56 Inch Premium Gold Ceiling Fan - Ivory | F15: 0 | I15: =E15-G15 -> 0 | K15: 1000 | Q15: =128+39+170 -> 337
A16: 4 | B16: CF5606/CF5606IV | C16: CF 5606 | D16: 56 Inch Premium Plus Ceiling Fan - Ivory | F16: 60 | I16: =E16-G16 -> 0 | Q16: =Q15*4*12 -> 16176 | V16: CF5601/CF5601IV | X16: 56 Inch Premium Ceiling Fan - Ivory
A17: 5 | B17: CF5607/CF5607IV | C17: CF 5607 | D17: 56 Inch Crown Ceiling Fan - Ivory | F17: 335 | I17: =E17-G17 -> 0 | K17: 50 | V17: CF5602/CF5602IV | X17: 56 Inch Speed King Ceiling Fan - Ivory
A18: 6 | B18: CF4801/CF4801IV | C18: CF 4801 | D18: 48 Inch Popular Ceiling Fan - Ivory | E18: 5000 | F18: 1100 | I18: =E18-G18 -> 5000 | V18: CF5603/CF5603IV | X18: Inch Premium Gold Ceiling Fan - Ivory
A19: 7 | B19: CF3601/CF3601IV | C19: CF 3601 | D19: 36 Inch Hero Ceiling Fan - Ivory | E19: 5000 | F19: 8000 | I19: =E19-G19 -> 5000 | V19: CF5606/CF5606IV | X19: 56 Inch Premium Plus Ceiling Fan - Ivory
A20: 8 | B20: CF2401/CF2401IV | C20: CF 2401 | D20: 24 Inch Super Ceiling Fan - Ivory | E20: 5000 | F20: 1091 | I20: =E20-G20 -> 5000 | V20: CF5607/CF5607IV | X20: 56 Inch Crown Ceiling Fan - Ivory
B22: CFB2401/FB2401IV | D22: {=_xlfn.XLOOKUP(B22:B31,'ERP Entry FG'!E:E,'ERP Entry FG'!F:F)} -> 24 Inch Super Ceiling Fan Blade - Ivory | F22: {=_xlfn.XLOOKUP(B22:B31,'ERP Entry FG'!E:E,'ERP Entry FG'!L:L,0)} -> 0 | V22: CF3601/CF3601IV | X22: 36 Inch Hero Ceiling Fan - Ivory
B23: CR3601IV | D23: 36 Inch Hero Ceiling Fan- Ivory (Without Regulator) | F23: 0 | V23: CF2401/CF2401IV | X23: 24 Inch Super Ceiling Fan - Ivory
B24: CFB3601/FB3601IV | D24: 36 Inch Hero Celling Fan Blade - Ivory | F24: 1
B25: CFB4801/FB4801IV | D25: 48 Inch Popular Celling Fan Blade- Ivory | F25: 0
B26: CF5601WH/CF5601WH | D26: 56 Inch Premium Ceiling Fan - White | F26: 49 | P26: =170*4*12 -> 8160
B27: CFB5601/FB5601IV | D27: 56 Inch Premium Ceiling Fan Blade - Ivory | F27: 0
B28: CR5601IV | D28: 56 Inch Premium Ceiling Fan- Ivory (Without Regulator) | F28: 2015
B29: CR5601WH | D29: 56 Inch Premium Ceiling Fan- White (Without Regulator) | F29: 56
B30: CG5606/CG5606IV | D30: 56 Inch Premium Plus Ceiling Fan With Gang Regulator - Ivory | F30: 0
B31: CR5606IV | D31: 56 Inch Premium Plus Ceiling Fan- Ivory (Without Regulator) | F31: 0

Sheet Stock
A1: MEP FAN LTD | Q1: Item Name | R1: Pending | S1: ERP Pending | T1: Daily Production | U1: Total
Q2: Ex-10 Aluminium | R2: =_xlfn.XLOOKUP(Q2,'Main Page'!C3:C20,'Main Page'!I3:I20,0) -> 5252 | T2: 5000 | U2: =SUM(S2:T2) -> 5000
A3: SL | B3: Category | C3: Item Code | D3: Item Description | E3: Unit | F3: BOM | G3: Total RM Consumption | H3: Store Stock | I3: Floor Stock | J3: Total RM Requirement | L3: Daily RM Consumption | M3: Store Stock | N3: Floor Stock | O3: Daily RM Requirement
A4: {=_xlfn._xlws.FILTER(BOM!A2:F1174,BOM!G2:G1174=Stock!Q2)} -> 1 | B4: Ceiling Raw | C4: 3101010023 | D4: FAN Ampere Tube-04 no | E4: Mtr | F4: 0.129 | G4: =IF(F4*$R$2=0,"",F4*$R$2) -> 677.508 | H4: {=_xlfn.XLOOKUP(C4:C44,'ERP Entry Stock'!G:G,'ERP Entry Stock'!J:J,0)} -> 3200.004 | I4: {=_xlfn.XLOOKUP(C4:C44,'ERP Entry Stock'!G:G,'ERP Entry Stock'!K:K,0)} -> 3475.627 | J4: =MAX(0,G4-H4-I4) -> 0 | L4: =F4*$U$2 -> 645 | M4: {=_xlfn.XLOOKUP(C4:C44,'ERP Entry Stock'!G:G,'ERP Entry Stock'!J:J,0)} -> 3200.004 | N4: {=_xlfn.XLOOKUP(C4:C44,'ERP Entry Stock'!G:G,'ERP Entry Stock'!K:K,0)} -> 3475.627 | O4: =MAX(0,L4-H4-I4) -> 0
A5: 2 | B5: Ceiling Raw | C5: 3101010094 | D5: Soldering Wire | E5: KG | F5: 0.001 | G5: =F5*$R$2 -> 5.252 | H5: 27.997 | I5: 5.991 | J5: =MAX(0,G5-H5-I5) -> 0 | L5: =F5*$U$2 -> 5 | M5: 27.997 | N5: 5.991 | O5: =MAX(0,L5-H5-I5) -> 0
A6: 3 | B6: Exhaust Raw | C6: 3102010013 | D6: 5/32 Inch, 9mm Screw | E6: KG | F6: 0.009 | G6: =F6*$R$2 -> 47.268 | H6: 0.004 | I6: 28.453 | J6: =MAX(0,G6-H6-I6) -> 18.811 | L6: =F6*$U$2 -> 45 | M6: 0.004 | N6: 28.453 | O6: =MAX(0,L6-H6-I6) -> 16.543
A7: 4 | B7: Exhaust Raw | C7: 3102010012 | D7: Cable 2x23/0.0076 | E7: Mtr | F7: 0.62 | G7: =F7*$R$2 -> 3256.24 | H7: 5000 | I7: 774.54 | J7: =MAX(0,G7-H7-I7) -> 0 | L7: =F7*$U$2 -> 3100 | M7: 5000 | N7: 774.54 | O7: =MAX(0,L7-H7-I7) -> 0
A8: 5 | B8: Exhaust Raw | C8: 3202010010 | D8: Exhaust Fan Base (10``) | E8: Pcs | F8: 1 | G8: =F8*$R$2 -> 5252 | H8: 3901 | I8: 5343 | J8: =MAX(0,G8-H8-I8) -> 0 | L8: =F8*$U$2 -> 5000 | M8: 3901 | N8: 5343 | O8: =MAX(0,L8-H8-I8) -> 0
A9: 6 | B9: Exhaust Raw | C9: 3202010017 | D9: Exhaust Fan Blade (10``) | E9: Pcs | F9: 1 | G9: =F9*$R$2 -> 5252 | H9: 3463 | I9: 816 | J9: =MAX(0,G9-H9-I9) -> 973 | L9: =F9*$U$2 -> 5000 | M9: 3463 | N9: 816 | O9: =MAX(0,L9-H9-I9) -> 721
A10: 7 | B10: Exhaust Raw | C10: 3102010022 | D10: Exhaust Fan Capacitor 1.5 µF | E10: Pcs | F10: 1 | G10: =F10*$R$2 -> 5252 | H10: 0 | I10: 5263 | J10: =MAX(0,G10-H10-I10) -> 0 | L10: =F10*$U$2 -> 5000 | M10: 0 | N10: 5263 | O10: =MAX(0,L10-H10-I10) -> 0 | X10: Ex-08 Copper
A11: 8 | B11: Exhaust Raw | C11: 3102010007 | D11: Exhaust Fan Capacitor Box | E11: Pcs | F11: 1 | G11: =F11*$R$2 -> 5252 | H11: 4572 | I11: 1646 | J11: =MAX(0,G11-H11-I11) -> 0 | L11: =F11*$U$2 -> 5000 | M11: 4572 | N11: 1646 | O11: =MAX(0,L11-H11-I11) -> 0 | X11: Ex-10 Copper
A12: 9 | B12: Exhaust Raw | C12: 3102010009 | D12: Exhaust Fan Clam | E12: Pcs | F12: 1 | G12: =F12*$R$2 -> 5252 | H12: 0 | I12: 18417 | J12: =MAX(0,G12-H12-I12) -> 0 | L12: =F12*$U$2 -> 5000 | M12: 0 | N12: 18417 | O12: =MAX(0,L12-H12-I12) -> 0 | X12: Ex-10 Aluminium
A13: 10 | B13: Exhaust Raw | C13: 3202010011 | D13: Exhaust Fan Cover (10``) | E13: Pcs | F13: 1 | G13: =F13*$R$2 -> 5252 | H13: 2460 | I13: 754 | J13: =MAX(0,G13-H13-I13) -> 2038 | L13: =F13*$U$2 -> 5000 | M13: 2460 | N13: 754 | O13: =MAX(0,L13-H13-I13) -> 1786 | X13: Ex-08 Aluminium
A14: 11 | B14: Exhaust Raw | C14: 3102010021 | D14: Exhaust Fan Motor (10``)-Alu | E14: Pcs | F14: 1 | G14: =F14*$R$2 -> 5252 | H14: 0 | I14: 2549 | J14: =MAX(0,G14-H14-I14) -> 2703 | L14: =F14*$U$2 -> 5000 | M14: 0 | N14: 2549 | O14: =MAX(0,L14-H14-I14) -> 2451 | X14: Capacitor 2.5
A15: 12 | B15: Exhaust Raw | C15: 3102010006 | D15: Exhaust Fan Show Cap With Pitol Bush | E15: Pcs | F15: 1 | G15: =F15*$R$2 -> 5252 | H15: 0 | I15: 3320 | J15: =MAX(0,G15-H15-I15) -> 1932 | L15: =F15*$U$2 -> 5000 | M15: 0 | N15: 3320 | O15: =MAX(0,L15-H15-I15) -> 1680 | X15: Capacitor 3.5
A16: 13 | B16: Exhaust Raw | C16: 3202010013 | D16: Exhaust Fan Shutter (10``) | E16: Pcs | F16: 3 | G16: =F16*$R$2 -> 15756 | H16: 465 | I16: 2434 | J16: =MAX(0,G16-H16-I16) -> 12857 | L16: =F16*$U$2 -> 15000 | M16: 465 | N16: 2434 | O16: =MAX(0,L16-H16-I16) -> 12101 | X16: CF 5601
A17: 14 | B17: Exhaust Raw | C17: 3202010012 | D17: Exhaust Fan Side Stand (10``) | E17: Pcs | F17: 1 | G17: =F17*$R$2 -> 5252 | H17: 7481 | I17: 4968 | J17: =MAX(0,G17-H17-I17) -> 0 | L17: =F17*$U$2 -> 5000 | M17: 7481 | N17: 4968 | O17: =MAX(0,L17-H17-I17) -> 0 | X17: CF 5602
A18: 15 | B18: Exhaust Raw | C18: 3102010010 | D18: Exhaust Fan Spring (FAN) | E18: KG | F18: 0.0028 | G18: =F18*$R$2 -> 14.7056 | H18: 0.0036 | I18: 0.0012 | J18: =MAX(0,G18-H18-I18) -> 14.7008 | L18: =F18*$U$2 -> 14 | M18: 0.0036 | N18: 0.0012 | O18: =MAX(0,L18-H18-I18) -> 13.9952 | X18: CF 5603
A19: 16 | B19: Exhaust Raw | C19: 3102010011 | D19: Exhaust Fan Spring Lock | E19: Pcs | F19: 1 | G19: =F19*$R$2 -> 5252 | H19: 3500 | I19: 7365 | J19: =MAX(0,G19-H19-I19) -> 0 | L19: =F19*$U$2 -> 5000 | M19: 3500 | N19: 7365 | O19: =MAX(0,L19-H19-I19) -> 0 | X19: CF 5606
A20: 17 | B20: Exhaust Raw | C20: 3202010014 | D20: Exhaust Fan Stick (10``) | E20: Pcs | F20: 1 | G20: =F20*$R$2 -> 5252 | H20: 8929 | I20: 1766 | J20: =MAX(0,G20-H20-I20) -> 0 | L20: =F20*$U$2 -> 5000 | M20: 8929 | N20: 1766 | O20: =MAX(0,L20-H20-I20) -> 0 | X20: CF 5607
A21: 18 | B21: Exhaust Raw | C21: 3102010010 | D21: Exhaust Fan Spring (FAN) | E21: Pcs | F21: 1 | G21: =F21*$R$2 -> 5252 | H21: 0.0036 | I21: 0.0012 | J21: =MAX(0,G21-H21-I21) -> 5251.9952 | L21: =F21*$U$2 -> 5000 | M21: 0.0036 | N21: 0.0012 | O21: =MAX(0,L21-H21-I21) -> 4999.9952 | X21: CF 4801
... A23: 20 | B23: Exhaust Raw | C23: 3202010008 | D23: HDPE Poly 20x24``-(Std.W.-0.015016 kg) | E23: KG | F23: 0.017 | G23: =F23*$R$2 -> 89.284 | H23: 505.002 | I23: 54.056 | J23: =MAX(0,G23-H23-I23) -> 0 | L23: =F23*$U$2 -> 85 | M23: 505.002 | N23: 54.056 | O23: =MAX(0,L23-H23-I23) -> 0 | X23: CF 2401
A24: 21 | B24: Exhaust Raw | C24: 3102010019 | D24: MEP Cable Tie -3.5x150mm | E24: Pcs | F24: 1 | G24: =F24*$R$2 -> 5252 | H24: 16000 | I24: 1187 | J24: =MAX(0,G24-H24-I24) -> 0 | L24: =F24*$U$2 -> 5000 | M24: 16000 | N24: 1187 | O24: =MAX(0,L24-H24-I24) -> 0
A25: 22 | B25: Exhaust Raw | C25: 3202010007 | D25: PP Band Fita | E25: KG | F25: 0.007 | G25: =F25*$R$2 -> 36.764 | H25: 94.87 | I25: 33.7123 | J25: =MAX(0,G25-H25-I25) -> 0 | L25: =F25*$U$2 -> 35 | M25: 94.87 | N25: 33.7123 | O25: =MAX(0,L25-H25-I25) -> 0
A26: 23 | B26: Packing Materials - FAN | C26: 3201010080 | D26: 10 Inch Exhaust Fan Body Carton (Alu) | E26: Pcs | F26: 1 | G26: =F26*$R$2 -> 5252 | H26: 516 | I26: 74 | J26: =MAX(0,G26-H26-I26) -> 4662 | L26: =F26*$U$2 -> 5000 | M26: 516 | N26: 74 | O26: =MAX(0,L26-H26-I26) -> 4410
A27: 24 | B27: Packing Materials - FAN | C27: 3201010081 | D27: Aero Flow Sticker | E27: Pcs | F27: 1 | G27: =F27*$R$2 -> 5252 | H27: 17750 | I27: 3263 | J27: =MAX(0,G27-H27-I27) -> 0 | L27: =F27*$U$2 -> 5000 | M27: 17750 | N27: 3263 | O27: =MAX(0,L27-H27-I27) -> 0
A28: 25 | B28: Packing Materials - FAN | C28: 3201010046 | D28: Carton Tape - (W=60mm,L=200m, MEP Print) | E28: Mtr | F28: 1.14 | G28: =F28*$R$2 -> 5987.28 | H28: 18952 | I28: 31826.915 | J28: =MAX(0,G28-H28-I28) -> 0 | L28: =F28*$U$2 -> 5700 | M28: 18952 | N28: 31826.915 | O28: =MAX(0,L28-H28-I28) -> 0
A29: 26 | B29: Packing Materials - FAN | C29: 3201010014 | D29: Fan QC Sticker | E29: Pcs | F29: 1 | G29: =F29*$R$2 -> 5252 | H29: 50500 | I29: 39511 | J29: =MAX(0,G29-H29-I29) -> 0 | L29: =F29*$U$2 -> 5000 | M29: 50500 | N29: 39511 | O29: =MAX(0,L29-H29-I29) -> 0
A30: 27 | B30: Packing Materials - FAN | C30: 3201010062 | D30: MEP Hologram Sticker | E30: Pcs | F30: 1 | G30: =F30*$R$2 -> 5252 | H30: 98100 | I30: 28412 | J30: =MAX(0,G30-H30-I30) -> 0 | L30: =F30*$U$2 -> 5000 | M30: 98100 | N30: 28412 | O30: =MAX(0,L30-H30-I30) -> 0
G31: =F31*$R$2 -> 0 | H31: 0 | I31: 0 | J31: =MAX(0,G31-H31-I31) -> 0 | L31: =F31*$U$2 -> 0 | M31: 0 | N31: 0 | O31: =MAX(0,L31-H31-I31) -> 0
G32: =F32*$R$2 -> 0 | H32: 0 | I32: 0 | J32: =MAX(0,G32-H32-I32) -> 0 | L32: =F32*$U$2 -> 0 | M32: 0 | N32: 0 | O32: =MAX(0,L32-H32-I32) -> 0
G33: =F33*$R$2 -> 0 | H33: 0 | I33: 0 | J33: =MAX(0,G33-H33-I33) -> 0 | L33: =F33*$U$2 -> 0 | M33: 0 | N33: 0 | O33: =MAX(0,L33-H33-I33) -> 0
G34: =F34*$R$2 -> 0 | H34: 0 | I34: 0 | J34: =MAX(0,G34-H34-I34) -> 0 | L34: =F34*$U$2 -> 0 | M34: 0 | N34: 0 | O34: =MAX(0,L34-H34-I34) -> 0
G35: =F35*$R$2 -> 0 | H35: 0 | I35: 0 | J35: =MAX(0,G35-H35-I35) -> 0 | L35: =F35*$U$2 -> 0 | M35: 0 | N35: 0 | O35: =MAX(0,L35-H35-I35) -> 0
G36: =F36*$R$2 -> 0 | H36: 0 | I36: 0 | J36: =MAX(0,G36-H36-I36) -> 0 | L36: =F36*$U$2 -> 0 | M36: 0 | N36: 0 | O36: =MAX(0,L36-H36-I36) -> 0
G37: =F37*$R$2 -> 0 | H37: 0 | I37: 0 | J37: =MAX(0,G37-H37-I37) -> 0 | L37: =F37*$U$2 -> 0 | M37: 0 | N37: 0 | O37: =MAX(0,L37-H37-I37) -> 0
G38: =F38*$R$2 -> 0 | H38: 0 | I38: 0 | J38: =MAX(0,G38-H38-I38) -> 0 | L38: =F38*$U$2 -> 0 | M38: 0 | N38: 0 | O38: =MAX(0,L38-H38-I38) -> 0
G39: =F39*$R$2 -> 0 | H39: 0 | I39: 0 | J39: =MAX(0,G39-H39-I39) -> 0 | L39: =F39*$U$2 -> 0 | M39: 0 | N39: 0 | O39: =MAX(0,L39-H39-I39) -> 0
G40: =F40*$R$2 -> 0 | H40: 0 | I40: 0 | J40: =MAX(0,G40-H40-I40) -> 0 | L40: =F40*$U$2 -> 0 | M40: 0 | N40: 0 | O40: =MAX(0,L40-H40-I40) -> 0
G41: =F41*$R$2 -> 0 | H41: 0 | I41: 0 | J41: =MAX(0,G41-H41-I41) -> 0 | L41: =F41*$U$2 -> 0 | M41: 0 | N41: 0 | O41: =MAX(0,L41-H41-I41) -> 0
...

Sheet ERP Entry Stock
A1: Warehouse Stock Position Report Detail(Closing)
A3: Closing Stock of Date-2026-08-29
A5: Reporting Time: 02:43 PM 29-08-2026
A6: S/L | B6: Company | C6: Group | D6: Category | E6: SubCategory | F6: Item Code | G6: FG | H6: Item Name | I6: Unit | J6: Store Qty | K6: Section Qty
A7: 1 | B7: FAN | E7: Fan Scrap | F7: 1500100001 | G7: 1500100001 | H7: Aluminium Bar Scrap | I7: KG | J7: 0 | K7: 7528.403
A8: 2 | B8: FAN | E8: Fan Scrap | F8: 1500100003 | G8: 1500100003 | H8: Silicon Sheet 25 Gage Scrap | I8: KG | J8: 0 | K8: 33798.194
A9: 3 | B9: FAN | E9: Fan Scrap | F9: 1500100014 | G9: 1500100014 | H9: Super Enamel Copper Scrap (Fan) | I9: KG | J9: 0 | K9: 0
A10: 4 | B10: FAN | E10: Ceiling Raw | F10: 200100002 | G10: 3101010001 | H10: Aluminum Ingot | I10: KG | J10: 34000 | K10: 2427.879
A11: 5 | B11: FAN | E11: Ceiling Raw | F11: 200100003 | G11: 3101010002 | H11: Aluminium Bar | I11: KG | J11: 0 | K11: 0
A12: 6 | B12: FAN | E12: Ceiling Raw | F12: 200100005 | G12: 3101010004 | H12: Aluminum Blade Sheet-1.22mm(18G) | I12: KG | J12: 9348 | K12: 14712.012
A13: 7 | B13: FAN | E13: Ceiling Raw | F13: 200100006 | G13: 3101010005 | H13: Silicon Sheet-0.51mm(25G) (Hard) | I13: KG | J13: 95315
A14: 8 | B14: FAN | E14: Ceiling Raw | F14: 200100007 | G14: 3101010006 | H14: Silicon Sheet 0.51mm (25G) Hard 7`` (179.9mm) | I14: KG | J14: 0 | K14: 84037.204
A15: 9 | B15: FAN | E15: Ceiling Raw | F15: 200100008 | G15: 3101010007 | H15: Silicon Sheet 0.51mm (25G) Hard 6`` (155.9mm) | I15: KG | J15: 0 | K15: 3313.749
A16: 10 | B16: FAN | E16: Ceiling Raw | F16: 200100009 | G16: 3101010008 | H16: Silicon Sheet 0.51mm (25G) Hard 5.5`` (142.8mm) | I16: KG | J16: 0 | K16: 12357.351
A17: 11 | B17: FAN | E17: Ceiling Raw | F17: 200100012 | G17: 3101010011 | H17: MS Shank Sheet 2.03mm(14G) (M Hard) | I17: KG | J17: 0 | K17: 10130.713
A18: 12 | B18: FAN | E18: Ceiling Raw | F18: 200100013 | G18: 3101010012 | H18: MS Shank/Clamp Sheet 1.83mm(15G) | I18: KG | J18: 0 | K18: 5751.224
A19: 13 | B19: FAN | E19: Ceiling Raw | F19: 200100014 | G19: 3101010013 | H19: MS Blade Sheet 0.61mm(23G) (Hard) | I19: KG | J19: 0 | K19: 7438.022
A20: 14 | B20: FAN | E20: Ceiling Raw | F20: 200100015 | G20: 3101010014 | H20: MS Blade Sheet 0.61mm(23G) (M Hard) | I20: KG | J20: 8205 | K20: 969.392
A21: 15 | B21: FAN | E21: Ceiling Raw | F21: 200100016 | G21: 3101010015 | H21: MS Pipe - OD=22mm, ID=18mm, T=2mm, L=20feet | I21: Feet | J21: 40000 | K21: 1560.85
A22: 16 | B22: FAN | E22: Ceiling Raw | F22: 200100017 | G22: 3101010016 | H22: Super Wire (SWG 33) / 0.253mm | I22: KG | J22: 6718.7 | K22: 17.29
A23: 17 | B23: FAN | E23: Ceiling Raw | F23: 200100018 | G23: 3101010017 | H23: Super Wire (SWG 34) / 0.233mm | I23: KG | J23: 10.38 | K23: 14.376
A24: 18 | B24: FAN | E24: Ceiling Raw | F24: 200100019 | G24: 3101010018 | H24: Super Wire (SWG 35) / 0.213mm | I24: KG | J24: 65.65 | K24: 39.22
A25: 19 | B25: FAN | E25: Ceiling Raw | F25: 200100020 | G25: 3101010019 | H25: Insulation Fiber 20 mm x 0.35mm | I25: KG | J25: 1728.733 | K25: 74.119
... A99: 93 | B99: FAN | E99: Ceiling Raw | F99: 200100116 | G99: 3101010117 | H99: Canopy White | I99: Pcs | J99: 10 | K99: 25
A100: 94 | B100: FAN | E100: Ceiling Raw | F100: 200100118 | G100: 3101010118 | H100: FAN Copper Rod 8mm | I100: KG | J100: 15900.29
A101: 95 | B101: FAN | E101: Ceiling Raw | F101: 200100119 | G101: 3101010119 | H101: Promotional Gang Regulator White (P512) | I101: Pcs | J101: 785 | K101: 0
A102: 96 | B102: FAN | E102: Ceiling Raw | F102: 200100120 | G102: 3101010120 | H102: XL/Shaft -178mm | I102: Pcs | J102: 742 | K102: 742
A103: 97 | B103: FAN | E103: Ceiling Raw | F103: 200100121 | G103: 3101010121 | H103: Down Pipe - 5607 | I103: Pcs | J103: 1100 | K103: 343
A104: 98 | B104: FAN | E104: Ceiling Raw | F104: 200100122 | G104: 3101010122 | H104: Neck - 5607 | I104: Pcs | J104: 700 | K104: 687
A105: 99 | B105: FAN | E105: Ceiling Raw | F105: 200100123 | G105: 3101010123 | H105: Canopy with Ring - 5607 | I105: Pcs | J105: 638 | K105: 198
A106: 100 | B106: FAN | E106: Ceiling Raw | F106: 200100124 | G106: 3101010124 | H106: Body Show Cap - 5607 | I106: Pcs | J106: 184 | K106: 192
A107: 101 | B107: FAN | E107: Ceiling Raw | F107: 200100125 | G107: 3101010125 | H107: Blade Show Cap - 5607 | I107: Pcs | J107: 0 | K107: 585
A108: 102 | B108: FAN | E108: Ceiling Raw | F108: 200100126 | G108: 3101010126 | H108: Capacitor Support- 5607 | I108: Pcs | J108: 0 | K108: 1164
A109: 103 | B109: FAN | E109: Ceiling Raw | F109: 200100127 | G109: 3101010127 | H109: Down Pipe Sira Pin (Big) | I109: Pcs | J109: 360 | K109: 191
A110: 104 | B110: FAN | E110: Ceiling Raw | F110: 200100128 | G110: 3101010128 | H110: Down Pipe Jam Nut - 5607 | I110: Pcs | J110: 200
A111: 105 | B111: FAN | E111: Ceiling Raw | F111: 200100129 | G111: 3101010129 | H111: Decorative Nut Bolt - 5607 | I111: Set | J111: 0 | K111: 2181
A112: 106 | B112: FAN | E112: Ceiling Raw | F112: 200100130 | G112: 3101010130 | H112: Body screw- 3/16`` x 35mm | I112: KG | J112: 10.001 | K112: 10.151
A113: 107 | B113: FAN | E113: Ceiling Raw | F113: 200100131 | G113: 3101010131 | H113: ADC12 Aluminium Ingot | I113: KG | J113: 0 | K113: 0
A114: 108 | B114: FAN | E114: Ceiling Raw | F114: 200100132 | G114: 3101010132 | H114: Aluminium Bar Scrap Local - FAN | I114: KG | J114: 0.002 | K114: 0.16994
A115: 109 | B115: FAN | E115: Ceiling Raw | F115: 200100133 | G115: 3101010133 | H115: Super Enamel Copper Scrap Local - FAN | I115: KG | J115: 42.63
...

Sheet ERP Entry FG
A1: S/L | B1: Company | C1: Category | D1: ERP CODE | E1: Code | F1: Item Name | G1: Unit | H1: Opening | I1: Opening Adjust | J1: Store Receive | K1: Section Receive | L1: Production Receive | M1: Damage Receive | N1: Others Receive | O1: Total Receive | P1: Consumption | Q1: WIP Issue | R1: Opening Adjust | S1: Issue To Reapir | T1: Issue To Damage | U1: In Transit | V1: Total Issue | W1: Closing | X1: Bin Closing | Y1: Diff | Z1: Remarks
A2: 1 | B2: FAN | C2: Finished Goods | D2: 100103576 | E2: EF0801OW/EF0801OW | F2: 08 Inch Fresh Air Exhaust Fan Off White | G2: Pcs | H2: 22 | J2: 0 | K2: 2690 | L2: 2690 | N2: 0 | O2: 5402 | Q2: 5402 | V2: 5402 | W2: 0 | X2: 0 | Y2: 0
A3: 2 | B3: FAN | C3: Finished Goods | D3: 100103575 | E3: EF1001OW/EF1001OW | F3: 10 Inch Fresh Air Exhaust Fan Off White | G3: Pcs | H3: 0 | J3: 0 | K3: 1554 | L3: 1554 | N3: 0 | O3: 3108 | Q3: 2990 | V3: 2990 | W3: 118 | X3: 118 | Y3: 0
A4: 3 | B4: FAN | C4: Finished Goods | D4: 100103577 | E4: MRTF1201 | F4: 12 Inch Swasti Rechargeable Table Fan | G4: Pcs | H4: 264 | J4: 0 | K4: 30 | L4: 30 | N4: 0 | O4: 324 | Q4: 324 | V4: 324 | W4: 0 | X4: 0 | Y4: 0
A5: 4 | B5: FAN | C5: Finished Goods | D5: 100103572 | E5: CF2401/CF2401IV | F5: 24 Inch Super Ceiling Fan - Ivory | G5: Pcs | H5: 0 | J5: 0 | K5: 1091 | L5: 1091 | N5: 0 | O5: 2182 | Q5: 2182 | V5: 2182 | W5: 0 | X5: 0 | Y5: 0
A6: 5 | B6: FAN | C6: Finished Goods | D6: 100103601 | E6: CFB2401/FB2401IV | F6: 24 Inch Super Ceiling Fan Blade - Ivory | G6: PKT | H6: 6 | J6: 0 | O6: 6 | V6: 0 | W6: 6 | X6: 6 | Y6: 0
A7: 6 | B7: FAN | C7: Finished Goods | D7: 100103571 | E7: CF3601/CF3601IV | F7: 36 Inch Hero Ceiling Fan - Ivory | G7: Pcs | H7: 13 | J7: 0 | K7: 8000 | L7: 8000 | N7: 0 | O7: 16013 | Q7: 14320 | U7: 1693 | V7: 16013 | W7: 0 | X7: 0 | Y7: 0
A8: 7 | B8: FAN | C8: Finished Goods | D8: 100104725 | E8: CR3601IV | F8: 36 Inch Hero Ceiling Fan- Ivory (Without Regulator) | G8: Pcs | H8: 15 | J8: 0 | O8: 15 | V8: 0 | W8: 15 | X8: 15 | Y8: 0
A9: 8 | B9: FAN | C9: Finished Goods | D9: 100103599 | E9: CFB3601/FB3601IV | F9: 36 Inch Hero Celling Fan Blade - Ivory | G9: PKT | H9: 9 | J9: 0 | K9: 1 | L9: 1 | N9: 0 | O9: 11 | Q9: 11 | V9: 11 | W9: 0 | X9: 0 | Y9: 0
A10: 9 | B10: FAN | C10: Finished Goods | D10: 100103570 | E10: CF4801/CF4801IV | F10: 48 Inch Popular Ceiling Fan - Ivory | G10: Pcs | H10: 0 | J10: 0 | K10: 1100 | L10: 1100 | N10: 0 | O10: 2200 | Q10: 2200 | V10: 2200 | W10: 0 | X10: 0 | Y10: 0
A11: 10 | B11: FAN | C11: Finished Goods | D11: 100103597 | E11: CFB4801/FB4801IV | F11: 48 Inch Popular Celling Fan Blade- Ivory | G11: PKT | H11: 7 | J11: 0 | O11: 7 | V11: 0 | W11: 7 | X11: 7 | Y11: 0
A12: 11 | B12: FAN | C12: Finished Goods | D12: 100104717 | E12: CF5607/CF5607IV | F12: 56 Inch Crown Ceiling Fan - Ivory | G12: Pcs | H12: 1 | J12: 0 | K12: 335 | L12: 335 | N12: 0 | O12: 671 | Q12: 671 | V12: 671 | W12: 0 | X12: 0 | Y12: 0
A13: 12 | B13: FAN | C13: Finished Goods | D13: 100103562 | E13: CF5601/CF5601IV | F13: 56 Inch Premium Ceiling Fan - Ivory | G13: Pcs | H13: 1 | J13: 1 | K13: 30786 | L13: 30786 | N13: 0 | O13: 61574 | Q13: 61573 | V13: 61573 | W13: 1 | X13: 1 | Y13: 0
A14: 13 | B14: FAN | C14: Finished Goods | D14: 100104179 | E14: CF5601WH/CF5601WH | F14: 56 Inch Premium Ceiling Fan - White | G14: Pcs | H14: 23 | J14: 0 | K14: 49 | L14: 49 | N14: 0 | O14: 121 | Q14: 49 | U14: 49 | V14: 98 | W14: 23 | X14: 23 | Y14: 0
A15: 14 | B15: FAN | C15: Finished Goods | D15: 100103587 | E15: CFB5601/FB5601IV | F15: 56 Inch Premium Ceiling Fan Blade - Ivory | G15: PKT | H15: 33 | J15: 0 | O15: 33 | Q15: 20 | V15: 20 | W15: 13 | X15: 13 | Y15: 0
A16: 15 | B16: FAN | C16: Finished Goods | D16: 100104745 | E16: CG5601/CG5601IV | F16: 56 Inch Premium Ceiling Fan With Gang Regulator - Ivory | G16: Pcs | H16: 0 | J16: 0 | K16: 48 | L16: 48 | N16: 0 | O16: 96 | Q16: 96 | V16: 96 | W16: 0 | X16: 0 | Y16: 0
A17: 16 | B17: FAN | C17: Finished Goods | D17: 100104722 | E17: CR5601IV | F17: 56 Inch Premium Ceiling Fan- Ivory (Without Regulator) | G17: Pcs | H17: 93 | J17: 0 | K17: 2015 | L17: 2015 | N17: 0 | O17: 4123 | Q17: 4123 | V17: 4123 | W17: 0 | X17: 0 | Y17: 0
A18: 17 | B18: FAN | C18: Finished Goods | D18: 100104726 | E18: CR5601WH | F18: 56 Inch Premium Ceiling Fan- White (Without Regulator) | G18: Pcs | H18: 0 | J18: 0 | K18: 56 | L18: 56 | N18: 0 | O18: 112 | Q18: 112 | V18: 112 | W18: 0 | X18: 0 | Y18: 0
A19: 18 | B19: FAN | C19: Finished Goods | D19: 100103564 | E19: CF5603/CF5603IV | F19: 56 Inch Premium Gold Ceiling Fan - Ivory | G19: Pcs | H19: 8 | J19: 0 | O19: 8 | V19: 0 | W19: 8 | X19: 8 | Y19: 0
A20: 19 | B20: FAN | C20: Finished Goods | D20: 100103567 | E20: CF5606/CF5606IV | F20: 56 Inch Premium Plus Ceiling Fan - Ivory | G20: Pcs | H20: 0 | J20: 0 | K20: 60 | L20: 60 | N20: 0 | O20: 120 | Q20: 112 | V20: 112 | W20: 8 | X20: 8 | Y20: 0
A21: 20 | B21: FAN | C21: Finished Goods | D21: 100105514 | E21: CG5606/CG5606IV | F21: 56 Inch Premium Plus Ceiling Fan With Gang Regulator - Ivory | G21: Pcs | H21: 4 | J21: 0 | O21: 4 | V21: 0 | W21: 4 | X21: 4 | Y21: 0
A22: 21 | B22: FAN | C22: Finished Goods | D22: 100105513 | E22: CR5606IV | F22: 56 Inch Premium Plus Ceiling Fan- Ivory (Without Regulator) | G22: Pcs | H22: 2 | J22: 0 | O22: 2 | V22: 0 | W22: 2 | X22: 2 | Y22: 0
A23: 22 | B23: FAN | C23: Finished Goods | D23: 100103563 | E23: CF5602/CF5602IV | F23: 56 Inch Speed King Ceiling Fan - Ivory | G23: Pcs | H23: 296 | J23: 0 | O23: 296 | Q23: 296 | V23: 296 | W23: 0 | X23: 0 | Y23: 0
A24: 23 | B24: FAN | C24: Finished Goods | D24: 100107316 | E24: EF1001AF | F24: Aero Flow 10`` Exhaust Fan | G24: Pcs | H24: 301 | J24: 0 | K24: 3078 | L24: 3078 | N24: 0 | O24: 6457 | Q24: 6456 | V24: 6456 | W24: 1 | X24: 1 | Y24: 0
A25: 24 | B25: FAN | C25: Finished Goods | D25: 100107315 | E25: EF0801AF | F25: Aero Flow 8`` Exhaust Fan | G25: Pcs | H25: 20 | J25: 0 | K25: 2626 | L25: 2626 | N25: 0 | O25: 5272 | Q25: 5272 | V25: 5272 | W25: 0 | X25: 0 | Y25: 0
A26: 25 | B26: FAN | C26: Finished Goods | D26: 100107035 | E26: CFCP001 | F26: Ceiling Fan Capacitor 2.5 uf | G26: Pcs | H26: 0 | J26: 0 | K26: 70128 | L26: 70128 | N26: 0 | O26: 140256 | Q26: 138576 | V26: 138576 | W26: 1680 | X26: 1680 | Y26: 0
A27: 26 | B27: FAN | C27: Finished Goods | D27: 100107036 | E27: CFCP002 | F27: Ceiling Fan Capacitor 3.5 uf | G27: Pcs | H27: 0 | J27: 0 | K27: 79872 | L27: 79872 | N27: 0 | O27: 159744 | Q27: 159744 | V27: 159744 | W27: 0 | X27: 0 | Y27: 0
A28: 27 | B28: FAN | C28: Finished Goods | D28: 1300100099 | E28: CFDP01/FDP001IV | F28: Celling Fan Down Pipe 1 Inch -Ivory | G28: Inch | H28: 2831 | J28: 0 | K28: 22000 | L28: 22000 | N28: 0 | O28: 46831 | Q28: 43332 | U28: 686 | V28: 44018 | W28: 2813 | X28: 2813 | Y28: 0
A29: 28 | B29: FAN | C29: Finished Goods | D29: 100103662 | E29: CFDP14/FDP014IV | F29: Celling Fan Down Pipe 14 Inch - Ivory | G29: Pcs | H29: 2 | J29: 0 | O29: 2 | V29: 0 | W29: 2 | X29: 2 | Y29: 0
A30: 29 | B30: FAN | C30: Finished Goods | D30: 100103647 | E30: CFDP60/FDP060IV | F30: Celling Fan Down Pipe 60 Inch Ivory | G30: Pcs | H30: 1 | J30: 0 | O30: 1 | V30: 0 | W30: 1 | X30: 1 | Y30: 0
A31: 30 | B31: FAN | C31: Finished Goods | D31: 100103726 | E31: 60477/FOA00500 | F31: MS Iron | G31: KG | H31: 254 | J31: 0 | O31: 254 | V31: 0 | W31: 254 | X31: 254 | Y31: 0
F32: Total | H32: 4206 | I32: 0 | J32: 1 | K32: 225519 | L32: 225519 | M32: 0 | N32: 0 | O32: 455245 | P32: 0 | Q32: 447861 | R32: 0 | S32: 0 | T32: 0 | U32: 2428 | V32: 450289 | W32: 4956 | X32: 4956 | Y32: 0

Sheet BSIC Entry
A1: MEP FAN LIMITED. | AA1: =IFERROR( IF(ISNUMBER(C1),C1,DATE(VALUE(RIGHT(C1,4)),VALUE(MID(SUBSTITUTE(C1,"/","-"),FIND("-",SUBSTITUTE(C1,"/","-"))+1,FIND("-",SUBSTITUTE(C1,"/","-"),FIND("-",SUBSTITUTE(C1,"/","-"))+1)-FIND("-",SUBSTITUTE(C1,"/","-"))-1)),VALUE(LEFT(SUBSTITUTE(C1,"/","-"),FIND("-",SUBSTITUTE(C1,"/","-"))-1)))), DATE(1995,1,1) ) -> 34700
AA2: =IFERROR( IF(ISNUMBER(C2),C2,DATE(VALUE(RIGHT(C2,4)),VALUE(MID(SUBSTITUTE(C2,"/","-"),FIND("-",SUBSTITUTE(C2,"/","-"))+1,FIND("-",SUBSTITUTE(C2,"/","-"),FIND("-",SUBSTITUTE(C2,"/","-"))+1)-FIND("-",SUBSTITUTE(C2,"/","-"))-1)),VALUE(LEFT(SUBSTITUTE(C2,"/","-"),FIND("-",SUBSTITUTE(C2,"/","-"))-1)))), DATE(1995,1,1) ) -> 34700
A3: Inter Sales Requisition Details Report | AA3: =IFERROR( IF(ISNUMBER(C3),C3,DATE(VALUE(RIGHT(C3,4)),VALUE(MID(SUBSTITUTE(C3,"/","-"),FIND("-",SUBSTITUTE(C3,"/","-"))+1,FIND("-",SUBSTITUTE(C3,"/","-"),FIND("-",SUBSTITUTE(C3,"/","-"))+1)-FIND("-",SUBSTITUTE(C3,"/","-"))-1)),VALUE(LEFT(SUBSTITUTE(C3,"/","-"),FIND("-",SUBSTITUTE(C3,"/","-"))-1)))), DATE(1995,1,1) ) -> 34700
AA4: =IFERROR( IF(ISNUMBER(C4),C4,DATE(VALUE(RIGHT(C4,4)),VALUE(MID(SUBSTITUTE(C4,"/","-"),FIND("-",SUBSTITUTE(C4,"/","-"))+1,FIND("-",SUBSTITUTE(C4,"/","-"),FIND("-",SUBSTITUTE(C4,"/","-"))+1)-FIND("-",SUBSTITUTE(C4,"/","-"))-1)),VALUE(LEFT(SUBSTITUTE(C4,"/","-"),FIND("-",SUBSTITUTE(C4,"/","-"))-1)))), DATE(1995,1,1) ) -> 34700
A5: 20-06-2026 To 29-08-2026 | AA5: =IFERROR( IF(ISNUMBER(C5),C5,DATE(VALUE(RIGHT(C5,4)),VALUE(MID(SUBSTITUTE(C5,"/","-"),FIND("-",SUBSTITUTE(C5,"/","-"))+1,FIND("-",SUBSTITUTE(C5,"/","-"),FIND("-",SUBSTITUTE(C5,"/","-"))+1)-FIND("-",SUBSTITUTE(C5,"/","-"))-1)),VALUE(LEFT(SUBSTITUTE(C5,"/","-"),FIND("-",SUBSTITUTE(C5,"/","-"))-1)))), DATE(1995,1,1) ) -> 34700
AA6: =IFERROR( IF(ISNUMBER(C6),C6,DATE(VALUE(RIGHT(C6,4)),VALUE(MID(SUBSTITUTE(C6,"/","-"),FIND("-",SUBSTITUTE(C6,"/","-"))+1,FIND("-",SUBSTITUTE(C6,"/","-"),FIND("-",SUBSTITUTE(C6,"/","-"))+1)-FIND("-",SUBSTITUTE(C6,"/","-"))-1)),VALUE(LEFT(SUBSTITUTE(C6,"/","-"),FIND("-",SUBSTITUTE(C6,"/","-"))-1)))), DATE(1995,1,1) ) -> 34700
A7: Reporting Time: 02:43 PM 29-08-2026 | AA7: =IFERROR( IF(ISNUMBER(C7),C7,DATE(VALUE(RIGHT(C7,4)),VALUE(MID(SUBSTITUTE(C7,"/","-"),FIND("-",SUBSTITUTE(C7,"/","-"))+1,FIND("-",SUBSTITUTE(C7,"/","-"),FIND("-",SUBSTITUTE(C7,"/","-"))+1)-FIND("-",SUBSTITUTE(C7,"/","-"))-1)),VALUE(LEFT(SUBSTITUTE(C7,"/","-"),FIND("-",SUBSTITUTE(C7,"/","-"))-1)))), DATE(1995,1,1) ) -> 34700
A8: S/L | B8: Req No | C8: Req Date | D8: Issue NO | E8: Company (Purchase) | F8: Company (Sales) | G8: Item Code | H8: Item Name | I8: Unit Name | J8: Req Qty | K8: Req Value | L8: Issue Qty | M8: Issue Value | N8: Pending Qty | O8: Pending Value | P8: Status | Q8: Entry By | R8: Entry At | AA8: =IFERROR( IF(ISNUMBER(C8),C8,DATE(VALUE(RIGHT(C8,4)),VALUE(MID(SUBSTITUTE(C8,"/","-"),FIND("-",SUBSTITUTE(C8,"/","-"))+1,FIND("-",SUBSTITUTE(C8,"/","-"),FIND("-",SUBSTITUTE(C8,"/","-"))+1)-FIND("-",SUBSTITUTE(C8,"/","-"))-1)),VALUE(LEFT(SUBSTITUTE(C8,"/","-"),FIND("-",SUBSTITUTE(C8,"/","-"))-1)))), DATE(1995,1,1) ) -> 34700
A9: 1 | B9: 2108 | C9: 20-06-2026 | E9: FAN | F9: Printing and Packaging | G9: 3202010001 | H9: HDPE Poly (L=22``, W=18``, T=0.025mm) | I9: KG | J9: 50 | K9: 14494.54 | M9: 0 | N9: 50 | O9: 14494.54 | P9: PENDING | Q9: 144 | R9: 46193.793 | AA9: =IFERROR( IF(ISNUMBER(C9),C9,DATE(VALUE(RIGHT(C9,4)),VALUE(MID(SUBSTITUTE(C9,"/","-"),FIND("-",SUBSTITUTE(C9,"/","-"))+1,FIND("-",SUBSTITUTE(C9,"/","-"),FIND("-",SUBSTITUTE(C9,"/","-"))+1)-FIND("-",SUBSTITUTE(C9,"/","-"))-1)),VALUE(LEFT(SUBSTITUTE(C9,"/","-"),FIND("-",SUBSTITUTE(C9,"/","-"))-1)))), DATE(1995,1,1) ) -> 46193
A10: 2 | B10: 2111 | C10: 21-06-2026 | D10: 1517415243 | E10: FAN | F10: Printing and Packaging | G10: 3202010001 | H10: HDPE Poly (L=22``, W=18``, T=0.025mm) | I10: KG | J10: 100 | K10: 28989.08 | L10: 42 | M10: 12175.41 | N10: 58 | O10: 16813.67 | P10: PENDING | Q10: 144 | R10: 46196.358 | AA10: =IFERROR( IF(ISNUMBER(C10),C10,DATE(VALUE(RIGHT(C10,4)),VALUE(MID(SUBSTITUTE(C10,"/","-"),FIND("-",SUBSTITUTE(C10,"/","-"))+1,FIND("-",SUBSTITUTE(C10,"/","-"),FIND("-",SUBSTITUTE(C10,"/","-"))+1)-FIND("-",SUBSTITUTE(C10,"/","-"))-1)),VALUE(LEFT(SUBSTITUTE(C10,"/","-"),FIND("-",SUBSTITUTE(C10,"/","-"))-1)))), DATE(1995,1,1) ) -> 46194
A11: 3 | B11: 2219 | C11: 26-07-2026 | D11: 1584715871 | E11: FAN | F11: Printing and Packaging | G11: 3202010001 | H11: HDPE Poly (L=22``, W=18``, T=0.025mm) | I11: KG | J11: 100 | K11: 28989.08 | L11: 100 | M11: 28989.08 | N11: 0 | O11: 0 | P11: PENDING | Q11: 144 | R11: 46229.685 | AA11: =IFERROR( IF(ISNUMBER(C11),C11,DATE(VALUE(RIGHT(C11,4)),VALUE(MID(SUBSTITUTE(C11,"/","-"),FIND("-",SUBSTITUTE(C11,"/","-"))+1,FIND("-",SUBSTITUTE(C11,"/","-"),FIND("-",SUBSTITUTE(C11,"/","-"))+1)-FIND("-",SUBSTITUTE(C11,"/","-"))-1)),VALUE(LEFT(SUBSTITUTE(C11,"/","-"),FIND("-",SUBSTITUTE(C11,"/","-"))-1)))), DATE(1995,1,1) ) -> 46229
A12: 4 | B12: 2282 | C12: 20-08-2026 | E12: FAN | F12: Printing and Packaging | G12: 3202010001 | H12: HDPE Poly (L=22``, W=18``, T=0.025mm) | I12: KG | J12: 0 | K12: 0 | M12: 0 | N12: 0 | O12: 0 | P12: CHECKED | Q12: 144 | R12: 46260.682 | AA12: =IFERROR( IF(ISNUMBER(C12),C12,DATE(VALUE(RIGHT(C12,4)),VALUE(MID(SUBSTITUTE(C12,"/","-"),FIND("-",SUBSTITUTE(C12,"/","-"))+1,FIND("-",SUBSTITUTE(C12,"/","-"),FIND("-",SUBSTITUTE(C12,"/","-"))+1)-FIND("-",SUBSTITUTE(C12,"/","-"))-1)),VALUE(LEFT(SUBSTITUTE(C12,"/","-"),FIND("-",SUBSTITUTE(C12,"/","-"))-1)))), DATE(1995,1,1) ) -> 46254
A13: 5 | B13: 2108 | C13: 20-06-2026 | E13: FAN | F13: Printing and Packaging | G13: 3202010002 | H13: 8 Inch Exhasust Fan Body Carton | I13: Pcs | J13: 2300 | K13: 98189.87 | M13: 0 | N13: 2300 | O13: 98189.87 | P13: PENDING | Q13: 144 | R13: 46193.793 | AA13: =IFERROR( IF(ISNUMBER(C13),C13,DATE(VALUE(RIGHT(C13,4)),VALUE(MID(SUBSTITUTE(C13,"/","-"),FIND("-",SUBSTITUTE(C13,"/","-"))+1,FIND("-",SUBSTITUTE(C13,"/","-"),FIND("-",SUBSTITUTE(C13,"/","-"))+1)-FIND("-",SUBSTITUTE(C13,"/","-"))-1)),VALUE(LEFT(SUBSTITUTE(C13,"/","-"),FIND("-",SUBSTITUTE(C13,"/","-"))-1)))), DATE(1995,1,1) ) -> 46193
A14: 6 | B14: 2111 | C14: 21-06-2026 | D14: 14747 | E14: FAN | F14: Printing and Packaging | G14: 3202010002 | H14: 8 Inch Exhasust Fan Body Carton | I14: Pcs | J14: 6100 | K14: 260416.61 | L14: 165 | M14: 7044.06 | N14: 5935 | O14: 253372.56 | P14: PENDING | Q14: 144 | R14: 46196.358 | AA14: =IFERROR( IF(ISNUMBER(C14),C14,DATE(VALUE(RIGHT(C14,4)),VALUE(MID(SUBSTITUTE(C14,"/","-"),FIND("-",SUBSTITUTE(C14,"/","-"))+1,FIND("-",SUBSTITUTE(C14,"/","-"),FIND("-",SUBSTITUTE(C14,"/","-"))+1)-FIND("-",SUBSTITUTE(C14,"/","-"))-1)),VALUE(LEFT(SUBSTITUTE(C14,"/","-"),FIND("-",SUBSTITUTE(C14,"/","-"))-1)))), DATE(1995,1,1) ) -> 46194
A15: 7 | B15: 2230 | C15: 46030 | D15: 1.5798158e+24 | E15: FAN | F15: Printing and Packaging | G15: 3202010002 | H15: 8 Inch Exhasust Fan Body Carton | I15: Pcs | J15: 3150 | K15: 134477.43 | L15: 2918 | M15: 124573.06 | N15: 232 | O15: 9904.37 | P15: PENDING | Q15: 144 | R15: 46236.692 | AA15: =IFERROR( IF(ISNUMBER(C15),C15,DATE(VALUE(RIGHT(C15,4)),VALUE(MID(SUBSTITUTE(C15,"/","-"),FIND("-",SUBSTITUTE(C15,"/","-"))+1,FIND("-",SUBSTITUTE(C15,"/","-"),FIND("-",SUBSTITUTE(C15,"/","-"))+1)-FIND("-",SUBSTITUTE(C15,"/","-"))-1)),VALUE(LEFT(SUBSTITUTE(C15,"/","-"),FIND("-",SUBSTITUTE(C15,"/","-"))-1)))), DATE(1995,1,1) ) -> 46030
A16: 8 | B16: 2108 | C16: 20-06-2026 | D16: 1509415175 | E16: FAN | F16: Printing and Packaging | G16: 3202010008 | H16: HDPE Poly (L=24``, W=20``, T=0.025mm) | I16: KG | J16: 55 | K16: 15875.2 | L16: 40.5 | M16: 11689.92 | N16: 14.5 | O16: 4185.28 | P16: PENDING | Q16: 144 | R16: 46193.793 | AA16: =IFERROR( IF(ISNUMBER(C16),C16,DATE(VALUE(RIGHT(C16,4)),VALUE(MID(SUBSTITUTE(C16,"/","-"),FIND("-",SUBSTITUTE(C16,"/","-"))+1,FIND("-",SUBSTITUTE(C16,"/","-"),FIND("-",SUBSTITUTE(C16,"/","-"))+1)-FIND("-",SUBSTITUTE(C16,"/","-"))-1)),VALUE(LEFT(SUBSTITUTE(C16,"/","-"),FIND("-",SUBSTITUTE(C16,"/","-"))-1)))), DATE(1995,1,1) ) -> 46193
A17: 9 | B17: 2111 | C17: 21-06-2026 | D17: 1.4766149e+59 | E17: FAN | F17: Printing and Packaging | G17: 3202010008 | H17: HDPE Poly (L=24``, W=20``, T=0.025mm) | I17: KG | J17: 275 | K17: 79376.02 | L17: 275 | M17: 79376.02 | N17: 0 | O17: 0 | P17: PENDING | Q17: 144 | R17: 46196.358 | AA17: =IFERROR( IF(ISNUMBER(C17),C17,DATE(VALUE(RIGHT(C17,4)),VALUE(MID(SUBSTITUTE(C17,"/","-"),FIND("-",SUBSTITUTE(C17,"/","-"))+1,FIND("-",SUBSTITUTE(C17,"/","-"),FIND("-",SUBSTITUTE(C17,"/","-"))+1)-FIND("-",SUBSTITUTE(C17,"/","-"))-1)),VALUE(LEFT(SUBSTITUTE(C17,"/","-"),FIND("-",SUBSTITUTE(C17,"/","-"))-1)))), DATE(1995,1,1) ) -> 46194
A18: 10 | B18: 2219 | C18: 26-07-2026 | D18: 1584715655 | E18: FAN | F18: Printing and Packaging | G18: 3202010008 | H18: HDPE Poly (L=24``, W=20``, T=0.025mm) | I18: KG | J18: 200 | K18: 57728.01 | L18: 200 | M18: 57728.01 | N18: 0 | O18: 0 | P18: PENDING | Q18: 144 | R18: 46229.685 | AA18: =IFERROR( IF(ISNUMBER(C18),C18,DATE(VALUE(RIGHT(C18,4)),VALUE(MID(SUBSTITUTE(C18,"/","-"),FIND("-",SUBSTITUTE(C18,"/","-"))+1,FIND("-",SUBSTITUTE(C18,"/","-"),FIND("-",SUBSTITUTE(C18,"/","-"))+1)-FIND("-",SUBSTITUTE(C18,"/","-"))-1)),VALUE(LEFT(SUBSTITUTE(C18,"/","-"),FIND("-",SUBSTITUTE(C18,"/","-"))-1)))), DATE(1995,1,1) ) -> 46229
A19: 11 | B19: 2282 | C19: 20-08-2026 | E19: FAN | F19: Printing and Packaging | G19: 3202010008 | H19: HDPE Poly (L=24``, W=20``, T=0.025mm) | I19: KG | J19: 150 | K19: 43296.01 | M19: 0 | N19: 150 | O19: 43296.01 | P19: CHECKED | Q19: 144 | R19: 46260.682 | AA19: =IFERROR( IF(ISNUMBER(C19),C19,DATE(VALUE(RIGHT(C19,4)),VALUE(MID(SUBSTITUTE(C19,"/","-"),FIND("-",SUBSTITUTE(C19,"/","-"))+1,FIND("-",SUBSTITUTE(C19,"/","-"),FIND("-",SUBSTITUTE(C19,"/","-"))+1)-FIND("-",SUBSTITUTE(C19,"/","-"))-1)),VALUE(LEFT(SUBSTITUTE(C19,"/","-"),FIND("-",SUBSTITUTE(C19,"/","-"))-1)))), DATE(1995,1,1) ) -> 46254
A20: 12 | B20: 2108 | C20: 20-06-2026 | E20: FAN | F20: Printing and Packaging | G20: 3202010009 | H20: 10 Inch Exhasust Fan Body Carton | I20: Pcs | J20: 1500 | K20: 78861.46 | M20: 0 | N20: 1500 | O20: 78861.46 | P20: PENDING | Q20: 144 | R20: 46193.793 | AA20: =IFERROR( IF(ISNUMBER(C20),C20,DATE(VALUE(RIGHT(C20,4)),VALUE(MID(SUBSTITUTE(C20,"/","-"),FIND("-",SUBSTITUTE(C20,"/","-"))+1,FIND("-",SUBSTITUTE(C20,"/","-"),FIND("-",SUBSTITUTE(C20,"/","-"))+1)-FIND("-",SUBSTITUTE(C20,"/","-"))-1)),VALUE(LEFT(SUBSTITUTE(C20,"/","-"),FIND("-",SUBSTITUTE(C20,"/","-"))-1)))), DATE(1995,1,1) ) -> 46193
A21: 13 | B21: 2111 | C21: 21-06-2026 | D21: 14747 | E21: FAN | F21: Printing and Packaging | G21: 3202010009 | H21: 10 Inch Exhasust Fan Body Carton | I21: Pcs | J21: 9200 | K21: 483683.62 | L21: 675 | M21: 35487.66 | N21: 8525 | O21: 448195.96 | P21: PENDING | Q21: 144 | R21: 46196.358 | AA21: =IFERROR( IF(ISNUMBER(C21),C21,DATE(VALUE(RIGHT(C21,4)),VALUE(MID(SUBSTITUTE(C21,"/","-"),FIND("-",SUBSTITUTE(C21,"/","-"))+1,FIND("-",SUBSTITUTE(C21,"/","-"),FIND("-",SUBSTITUTE(C21,"/","-"))+1)-FIND("-",SUBSTITUTE(C21,"/","-"))-1)),VALUE(LEFT(SUBSTITUTE(C21,"/","-"),FIND("-",SUBSTITUTE(C21,"/","-"))-1)))), DATE(1995,1,1) ) -> 46194
A22: 14 | B22: 2230 | C22: 46030 | D22: 1.5886159e+29 | E22: FAN | F22: Printing and Packaging | G22: 3202010009 | H22: 10 Inch Exhasust Fan Body Carton | I22: Pcs | J22: 2650 | K22: 139321.91 | L22: 2575 | M22: 135378.84 | N22: 75 | O22: 3943.07 | P22: PENDING | Q22: 144 | R22: 46236.692 | AA22: =IFERROR( IF(ISNUMBER(C22),C22,DATE(VALUE(RIGHT(C22,4)),VALUE(MID(SUBSTITUTE(C22,"/","-"),FIND("-",SUBSTITUTE(C22,"/","-"))+1,FIND("-",SUBSTITUTE(C22,"/","-"),FIND("-",SUBSTITUTE(C22,"/","-"))+1)-FIND("-",SUBSTITUTE(C22,"/","-"))-1)),VALUE(LEFT(SUBSTITUTE(C22,"/","-"),FIND("-",SUBSTITUTE(C22,"/","-"))-1)))), DATE(1995,1,1) ) -> 46030
A23: 15 | B23: 2108 | C23: 20-06-2026 | E23: FAN | F23: Printing and Packaging | G23: 3202010015 | H23: Guarantee Card (Exhaust Fan) | I23: Pcs | J23: 6200 | K23: 1807.27 | M23: 0 | N23: 6200 | O23: 1807.27 | P23: PENDING | Q23: 144 | R23: 46193.793 | AA23: =IFERROR( IF(ISNUMBER(C23),C23,DATE(VALUE(RIGHT(C23,4)),VALUE(MID(SUBSTITUTE(C23,"/","-"),FIND("-",SUBSTITUTE(C23,"/","-"))+1,FIND("-",SUBSTITUTE(C23,"/","-"),FIND("-",SUBSTITUTE(C23,"/","-"))+1)-FIND("-",SUBSTITUTE(C23,"/","-"))-1)),VALUE(LEFT(SUBSTITUTE(C23,"/","-"),FIND("-",SUBSTITUTE(C23,"/","-"))-1)))), DATE(1995,1,1) ) -> 46193
A24: 16 | B24: 2111 | C24: 21-06-2026 | D24: 14720 | E24: FAN | F24: Printing and Packaging | G24: 3202010015 | H24: Guarantee Card (Exhaust Fan) | I24: Pcs | J24: 15500 | K24: 4518.18 | L24: 1000 | M24: 291.5 | N24: 14500 | O24: 4226.68 | P24: PENDING | Q24: 144 | R24: 46196.358 | AA24: =IFERROR( IF(ISNUMBER(C24),C24,DATE(VALUE(RIGHT(C24,4)),VALUE(MID(SUBSTITUTE(C24,"/","-"),FIND("-",SUBSTITUTE(C24,"/","-"))+1,FIND("-",SUBSTITUTE(C24,"/","-"),FIND("-",SUBSTITUTE(C24,"/","-"))+1)-FIND("-",SUBSTITUTE(C24,"/","-"))-1)),VALUE(LEFT(SUBSTITUTE(C24,"/","-"),FIND("-",SUBSTITUTE(C24,"/","-"))-1)))), DATE(1995,1,1) ) -> 46194
A25: 17 | B25: 2230 | C25: 46030 | D25: 15428 | E25: FAN | F25: Printing and Packaging | G25: 3202010015 | H25: Guarantee Card (Exhaust Fan) | I25: Pcs | J25: 6000 | K25: 1748.97 | L25: 6000 | M25: 1748.97 | N25: 0 | O25: 0 | P25: PENDING | Q25: 144 | R25: 46236.692 | AA25: =IFERROR( IF(ISNUMBER(C25),C25,DATE(VALUE(RIGHT(C25,4)),VALUE(MID(SUBSTITUTE(C25,"/","-"),FIND("-",SUBSTITUTE(C25,"/","-"))+1,FIND("-",SUBSTITUTE(C25,"/","-"),FIND("-",SUBSTITUTE(C25,"/","-"))+1)-FIND("-",SUBSTITUTE(C25,"/","-"))-1)),VALUE(LEFT(SUBSTITUTE(C25,"/","-"),FIND("-",SUBSTITUTE(C25,"/","-"))-1)))), DATE(1995,1,1) ) -> 46030
A26: 18 | B26: 2108 | C26: 20-06-2026 | E26: FAN | F26: Printing and Packaging | G26: 3202010016 | H26: Air Fresher Sticker | I26: Pcs | J26: 6300 | K26: 1150.64 | M26: 0 | N26: 6300 | O26: 1150.64 | P26: PENDING | Q26: 144 | R26: 46193.793 | AA26: =IFERROR( IF(ISNUMBER(C26),C26,DATE(VALUE(RIGHT(C26,4)),VALUE(MID(SUBSTITUTE(C26,"/","-"),FIND("-",SUBSTITUTE(C26,"/","-"))+1,FIND("-",SUBSTITUTE(C26,"/","-"),FIND("-",SUBSTITUTE(C26,"/","-"))+1)-FIND("-",SUBSTITUTE(C26,"/","-"))-1)),VALUE(LEFT(SUBSTITUTE(C26,"/","-"),FIND("-",SUBSTITUTE(C26,"/","-"))-1)))), DATE(1995,1,1) ) -> 46193
A27: 19 | B27: 2111 | C27: 21-06-2026 | D27: 1523214948 | E27: FAN | F27: Printing and Packaging | G27: 3202010016 | H27: Air Fresher Sticker | I27: Pcs | J27: 15500 | K27: 2830.94 | L27: 300 | M27: 54.79 | N27: 15200 | O27: 2776.15 | P27: PENDING | Q27: 144 | R27: 46196.358 | AA27: =IFERROR( IF(ISNUMBER(C27),C27,DATE(VALUE(RIGHT(C27,4)),VALUE(MID(SUBSTITUTE(C27,"/","-"),FIND("-",SUBSTITUTE(C27,"/","-"))+1,FIND("-",SUBSTITUTE(C27,"/","-"),FIND("-",SUBSTITUTE(C27,"/","-"))+1)-FIND("-",SUBSTITUTE(C27,"/","-"))-1)),VALUE(LEFT(SUBSTITUTE(C27,"/","-"),FIND("-",SUBSTITUTE(C27,"/","-"))-1)))), DATE(1995,1,1) ) -> 46194
A28: 20 | B28: 2230 | C28: 46030 | D28: 1542815554 | E28: FAN | F28: Printing and Packaging | G28: 3202010016 | H28: Air Fresher Sticker | I28: Pcs | J28: 6000 | K28: 1095.85 | L28: 6000 | M28: 1095.85 | N28: 0 | O28: 0 | P28: PENDING | Q28: 144 | R28: 46236.692 | AA28: =IFERROR( IF(ISNUMBER(C28),C28,DATE(VALUE(RIGHT(C28,4)),VALUE(MID(SUBSTITUTE(C28,"/","-"),FIND("-",SUBSTITUTE(C28,"/","-"))+1,FIND("-",SUBSTITUTE(C28,"/","-"),FIND("-",SUBSTITUTE(C28,"/","-"))+1)-FIND("-",SUBSTITUTE(C28,"/","-"))-1)),VALUE(LEFT(SUBSTITUTE(C28,"/","-"),FIND("-",SUBSTITUTE(C28,"/","-"))-1)))), DATE(1995,1,1) ) -> 46030
A29: 21 | B29: 2117 | C29: 21-06-2026 | D29: 148521485114471 | E29: FAN | F29: Printing and Packaging | G29: 3201010002 | H29: FAN Shank Paper | I29: Pcs | J29: 136500 | K29: 209358.94 | L29: 136500 | M29: 209358.94 | N29: 0 | O29: 0 | P29: PENDING | Q29: 144 | R29: 46196.36 | AA29: =IFERROR( IF(ISNUMBER(C29),C29,DATE(VALUE(RIGHT(C29,4)),VALUE(MID(SUBSTITUTE(C29,"/","-"),FIND("-",SUBSTITUTE(C29,"/","-"))+1,FIND("-",SUBSTITUTE(C29,"/","-"),FIND("-",SUBSTITUTE(C29,"/","-"))+1)-FIND("-",SUBSTITUTE(C29,"/","-"))-1)),VALUE(LEFT(SUBSTITUTE(C29,"/","-"),FIND("-",SUBSTITUTE(C29,"/","-"))-1)))), DATE(1995,1,1) ) -> 46194
A30: 22 | B30: 2206 | C30: 22-07-2026 | D30: 15333 | E30: FAN | F30: Printing and Packaging | G30: 3201010002 | H30: FAN Shank Paper | I30: Pcs | J30: 136500 | K30: 209358.94 | L30: 136500 | M30: 209358.94 | N30: 0 | O30: 0 | P30: PENDING | Q30: 144 | R30: 46228.398 | AA30: =IFERROR( IF(ISNUMBER(C30),C30,DATE(VALUE(RIGHT(C30,4)),VALUE(MID(SUBSTITUTE(C30,"/","-"),FIND("-",SUBSTITUTE(C30,"/","-"))+1,FIND("-",SUBSTITUTE(C30,"/","-"),FIND("-",SUBSTITUTE(C30,"/","-"))+1)-FIND("-",SUBSTITUTE(C30,"/","-"))-1)),VALUE(LEFT(SUBSTITUTE(C30,"/","-"),FIND("-",SUBSTITUTE(C30,"/","-"))-1)))), DATE(1995,1,1) ) -> 46225
A31: 23 | B31: 2283 | C31: 20-08-2026 | E31: FAN | F31: Printing and Packaging | G31: 3201010002 | H31: FAN Shank Paper | I31: Pcs | J31: 129780 | K31: 199052.04 | M31: 0 | N31: 129780 | O31: 199052.04 | P31: CHECKED | Q31: 144 | R31: 46260.691 | AA31: =IFERROR( IF(ISNUMBER(C31),C31,DATE(VALUE(RIGHT(C31,4)),VALUE(MID(SUBSTITUTE(C31,"/","-"),FIND("-",SUBSTITUTE(C31,"/","-"))+1,FIND("-",SUBSTITUTE(C31,"/","-"),FIND("-",SUBSTITUTE(C31,"/","-"))+1)-FIND("-",SUBSTITUTE(C31,"/","-"))-1)),VALUE(LEFT(SUBSTITUTE(C31,"/","-"),FIND("-",SUBSTITUTE(C31,"/","-"))-1)))), DATE(1995,1,1) ) -> 46254
A32: 24 | B32: 2117 | C32: 21-06-2026 | D32: 1464715285 | E32: FAN | F32: Printing and Packaging | G32: 3201010004 | H32: Body Sticker-5601 | I32: Pcs | J32: 40425 | K32: 12216.85 | L32: 40425 | M32: 12216.85 | N32: 0 | O32: 0 | P32: PENDING | Q32: 144 | R32: 46196.36 | AA32: =IFERROR( IF(ISNUMBER(C32),C32,DATE(VALUE(RIGHT(C32,4)),VALUE(MID(SUBSTITUTE(C32,"/","-"),FIND("-",SUBSTITUTE(C32,"/","-"))+1,FIND("-",SUBSTITUTE(C32,"/","-"),FIND("-",SUBSTITUTE(C32,"/","-"))+1)-FIND("-",SUBSTITUTE(C32,"/","-"))-1)),VALUE(LEFT(SUBSTITUTE(C32,"/","-"),FIND("-",SUBSTITUTE(C32,"/","-"))-1)))), DATE(1995,1,1) ) -> 46194
A33: 25 | B33: 2206 | C33: 22-07-2026 | D33: 15333 | E33: FAN | F33: Printing and Packaging | G33: 3201010004 | H33: Body Sticker-5601 | I33: Pcs | J33: 31500 | K33: 9519.63 | L33: 31500 | M33: 9519.63 | N33: 0 | O33: 0 | P33: PENDING | Q33: 144 | R33: 46228.398 | AA33: =IFERROR( IF(ISNUMBER(C33),C33,DATE(VALUE(RIGHT(C33,4)),VALUE(MID(SUBSTITUTE(C33,"/","-"),FIND("-",SUBSTITUTE(C33,"/","-"))+1,FIND("-",SUBSTITUTE(C33,"/","-"),FIND("-",SUBSTITUTE(C33,"/","-"))+1)-FIND("-",SUBSTITUTE(C33,"/","-"))-1)),VALUE(LEFT(SUBSTITUTE(C33,"/","-"),FIND("-",SUBSTITUTE(C33,"/","-"))-1)))), DATE(1995,1,1) ) -> 46225
A34: 26 | B34: 2283 | C34: 20-08-2026 | E34: FAN | F34: Printing and Packaging | G34: 3201010006 | H34: Body Sticker Speed King | I34: Pcs | J34: 10500 | K34: 3152.5 | M34: 0 | N34: 10500 | O34: 3152.5 | P34: CHECKED | Q34: 144 | R34: 46260.691 | AA34: =IFERROR( IF(ISNUMBER(C34),C34,DATE(VALUE(RIGHT(C34,4)),VALUE(MID(SUBSTITUTE(C34,"/","-"),FIND("-",SUBSTITUTE(C34,"/","-"))+1,FIND("-",SUBSTITUTE(C34,"/","-"),FIND("-",SUBSTITUTE(C34,"/","-"))+1)-FIND("-",SUBSTITUTE(C34,"/","-"))-1)),VALUE(LEFT(SUBSTITUTE(C34,"/","-"),FIND("-",SUBSTITUTE(C34,"/","-"))-1)))), DATE(1995,1,1) ) -> 46254
A35: 27 | B35: 2206 | C35: 22-07-2026 | D35: 15333 | E35: FAN | F35: Printing and Packaging | G35: 3201010007 | H35: Body Sticker-4801 | I35: Pcs | J35: 5250 | K35: 1503.11 | L35: 5250 | M35: 1503.11 | N35: 0 | O35: 0 | P35: PENDING | Q35: 144 | R35: 46228.398 | AA35: =IFERROR( IF(ISNUMBER(C35),C35,DATE(VALUE(RIGHT(C35,4)),VALUE(MID(SUBSTITUTE(C35,"/","-"),FIND("-",SUBSTITUTE(C35,"/","-"))+1,FIND("-",SUBSTITUTE(C35,"/","-"),FIND("-",SUBSTITUTE(C35,"/","-"))+1)-FIND("-",SUBSTITUTE(C35,"/","-"))-1)),VALUE(LEFT(SUBSTITUTE(C35,"/","-"),FIND("-",SUBSTITUTE(C35,"/","-"))-1)))), DATE(1995,1,1) ) -> 46225
A36: 28 | B36: 2206 | C36: 22-07-2026 | D36: 15333 | E36: FAN | F36: Printing and Packaging | G36: 3201010008 | H36: Body Sticker-3601 | I36: Pcs | J36: 5250 | K36: 1525.91 | L36: 5250 | M36: 1525.91 | N36: 0 | O36: 0 | P36: PENDING | Q36: 144 | R36: 46228.398 | AA36: =IFERROR( IF(ISNUMBER(C36),C36,DATE(VALUE(RIGHT(C36,4)),VALUE(MID(SUBSTITUTE(C36,"/","-"),FIND("-",SUBSTITUTE(C36,"/","-"))+1,FIND("-",SUBSTITUTE(C36,"/","-"),FIND("-",SUBSTITUTE(C36,"/","-"))+1)-FIND("-",SUBSTITUTE(C36,"/","-"))-1)),VALUE(LEFT(SUBSTITUTE(C36,"/","-"),FIND("-",SUBSTITUTE(C36,"/","-"))-1)))), DATE(1995,1,1) ) -> 46225
A37: 29 | B37: 2283 | C37: 20-08-2026 | E37: FAN | F37: Printing and Packaging | G37: 3201010008 | H37: Body Sticker-3601 | I37: Pcs | J37: 5000 | K37: 1453.25 | M37: 0 | N37: 5000 | O37: 1453.25 | P37: CHECKED | Q37: 144 | R37: 46260.691 | AA37: =IFERROR( IF(ISNUMBER(C37),C37,DATE(VALUE(RIGHT(C37,4)),VALUE(MID(SUBSTITUTE(C37,"/","-"),FIND("-",SUBSTITUTE(C37,"/","-"))+1,FIND("-",SUBSTITUTE(C37,"/","-"),FIND("-",SUBSTITUTE(C37,"/","-"))+1)-FIND("-",SUBSTITUTE(C37,"/","-"))-1)),VALUE(LEFT(SUBSTITUTE(C37,"/","-"),FIND("-",SUBSTITUTE(C37,"/","-"))-1)))), DATE(1995,1,1) ) -> 46254
A38: 30 | B38: 2117 | C38: 21-06-2026 | E38: FAN | F38: Printing and Packaging | G38: 3201010009 | H38: Body Sticker-2401 | I38: Pcs | J38: 5250 | K38: 1886.17 | M38: 0 | N38: 5250 | O38: 1886.17 | P38: PENDING | Q38: 144 | R38: 46196.36 | AA38: =IFERROR( IF(ISNUMBER(C38),C38,DATE(VALUE(RIGHT(C38,4)),VALUE(MID(SUBSTITUTE(C38,"/","-"),FIND("-",SUBSTITUTE(C38,"/","-"))+1,FIND("-",SUBSTITUTE(C38,"/","-"),FIND("-",SUBSTITUTE(C38,"/","-"))+1)-FIND("-",SUBSTITUTE(C38,"/","-"))-1)),VALUE(LEFT(SUBSTITUTE(C38,"/","-"),FIND("-",SUBSTITUTE(C38,"/","-"))-1)))), DATE(1995,1,1) ) -> 46194
A39: 31 | B39: 2206 | C39: 22-07-2026 | D39: 15338 | E39: FAN | F39: Printing and Packaging | G39: 3201010009 | H39: Body Sticker-2401 | I39: Pcs | J39: 5250 | K39: 1886.17 | L39: 5000 | M39: 1796.35 | N39: 250 | O39: 89.82 | P39: PENDING | Q39: 144 | R39: 46228.398 | AA39: =IFERROR( IF(ISNUMBER(C39),C39,DATE(VALUE(RIGHT(C39,4)),VALUE(MID(SUBSTITUTE(C39,"/","-"),FIND("-",SUBSTITUTE(C39,"/","-"))+1,FIND("-",SUBSTITUTE(C39,"/","-"),FIND("-",SUBSTITUTE(C39,"/","-"))+1)-FIND("-",SUBSTITUTE(C39,"/","-"))-1)),VALUE(LEFT(SUBSTITUTE(C39,"/","-"),FIND("-",SUBSTITUTE(C39,"/","-"))-1)))), DATE(1995,1,1) ) -> 46225
A40: 32 | B40: 2117 | C40: 21-06-2026 | D40: 1579414576 | E40: FAN | F40: Printing and Packaging | G40: 3201010010 | H40: Fan Canopy Sticker | I40: Pcs | J40: 93450 | K40: 45924.6 | L40: 33050 | M40: 16241.93 | N40: 60400 | O40: 29682.67 | P40: PENDING | Q40: 144 | R40: 46196.36 | AA40: =IFERROR( IF(ISNUMBER(C40),C40,DATE(VALUE(RIGHT(C40,4)),VALUE(MID(SUBSTITUTE(C40,"/","-"),FIND("-",SUBSTITUTE(C40,"/","-"))+1,FIND("-",SUBSTITUTE(C40,"/","-"),FIND("-",SUBSTITUTE(C40,"/","-"))+1)-FIND("-",SUBSTITUTE(C40,"/","-"))-1)),VALUE(LEFT(SUBSTITUTE(C40,"/","-"),FIND("-",SUBSTITUTE(C40,"/","-"))-1)))), DATE(1995,1,1) ) -> 46194
...

Sheet Plastic Entry
A1: MEP FAN LIMITED. | AA1: =IFERROR( IF(ISNUMBER(C1),C1,DATE(VALUE(RIGHT(C1,4)),VALUE(MID(SUBSTITUTE(C1,"/","-"),FIND("-",SUBSTITUTE(C1,"/","-"))+1,FIND("-",SUBSTITUTE(C1,"/","-"),FIND("-",SUBSTITUTE(C1,"/","-"))+1)-FIND("-",SUBSTITUTE(C1,"/","-"))-1)),VALUE(LEFT(SUBSTITUTE(C1,"/","-"),FIND("-",SUBSTITUTE(C1,"/","-"))-1)))), DATE(1995,1,1) ) -> 34700
AA2: =IFERROR( IF(ISNUMBER(C2),C2,DATE(VALUE(RIGHT(C2,4)),VALUE(MID(SUBSTITUTE(C2,"/","-"),FIND("-",SUBSTITUTE(C2,"/","-"))+1,FIND("-",SUBSTITUTE(C2,"/","-"),FIND("-",SUBSTITUTE(C2,"/","-"))+1)-FIND("-",SUBSTITUTE(C2,"/","-"))-1)),VALUE(LEFT(SUBSTITUTE(C2,"/","-"),FIND("-",SUBSTITUTE(C2,"/","-"))-1)))), DATE(1995,1,1) ) -> 34700
A3: Inter Sales Requisition Details Report | AA3: =IFERROR( IF(ISNUMBER(C3),C3,DATE(VALUE(RIGHT(C3,4)),VALUE(MID(SUBSTITUTE(C3,"/","-"),FIND("-",SUBSTITUTE(C3,"/","-"))+1,FIND("-",SUBSTITUTE(C3,"/","-"),FIND("-",SUBSTITUTE(C3,"/","-"))+1)-FIND("-",SUBSTITUTE(C3,"/","-"))-1)),VALUE(LEFT(SUBSTITUTE(C3,"/","-"),FIND("-",SUBSTITUTE(C3,"/","-"))-1)))), DATE(1995,1,1) ) -> 34700
AA4: =IFERROR( IF(ISNUMBER(C4),C4,DATE(VALUE(RIGHT(C4,4)),VALUE(MID(SUBSTITUTE(C4,"/","-"),FIND("-",SUBSTITUTE(C4,"/","-"))+1,FIND("-",SUBSTITUTE(C4,"/","-"),FIND("-",SUBSTITUTE(C4,"/","-"))+1)-FIND("-",SUBSTITUTE(C4,"/","-"))-1)),VALUE(LEFT(SUBSTITUTE(C4,"/","-"),FIND("-",SUBSTITUTE(C4,"/","-"))-1)))), DATE(1995,1,1) ) -> 34700
A5: 20-06-2026 To 29-08-2026 | AA5: =IFERROR( IF(ISNUMBER(C5),C5,DATE(VALUE(RIGHT(C5,4)),VALUE(MID(SUBSTITUTE(C5,"/","-"),FIND("-",SUBSTITUTE(C5,"/","-"))+1,FIND("-",SUBSTITUTE(C5,"/","-"),FIND("-",SUBSTITUTE(C5,"/","-"))+1)-FIND("-",SUBSTITUTE(C5,"/","-"))-1)),VALUE(LEFT(SUBSTITUTE(C5,"/","-"),FIND("-",SUBSTITUTE(C5,"/","-"))-1)))), DATE(1995,1,1) ) -> 34700
AA6: =IFERROR( IF(ISNUMBER(C6),C6,DATE(VALUE(RIGHT(C6,4)),VALUE(MID(SUBSTITUTE(C6,"/","-"),FIND("-",SUBSTITUTE(C6,"/","-"))+1,FIND("-",SUBSTITUTE(C6,"/","-"),FIND("-",SUBSTITUTE(C6,"/","-"))+1)-FIND("-",SUBSTITUTE(C6,"/","-"))-1)),VALUE(LEFT(SUBSTITUTE(C6,"/","-"),FIND("-",SUBSTITUTE(C6,"/","-"))-1)))), DATE(1995,1,1) ) -> 34700
A7: Reporting Time: 02:43 PM 29-08-2026 | AA7: =IFERROR( IF(ISNUMBER(C7),C7,DATE(VALUE(RIGHT(C7,4)),VALUE(MID(SUBSTITUTE(C7,"/","-"),FIND("-",SUBSTITUTE(C7,"/","-"))+1,FIND("-",SUBSTITUTE(C7,"/","-"),FIND("-",SUBSTITUTE(C7,"/","-"))+1)-FIND("-",SUBSTITUTE(C7,"/","-"))-1)),VALUE(LEFT(SUBSTITUTE(C7,"/","-"),FIND("-",SUBSTITUTE(C7,"/","-"))-1)))), DATE(1995,1,1) ) -> 34700
A8: S/L | B8: Req No | C8: Req Date | D8: Issue NO | E8: Company (Purchase) | F8: Company (Sales) | G8: Item Code | H8: Item Name | I8: Unit Name | J8: Req Qty | K8: Req Value | L8: Issue Qty | M8: Issue Value | N8: Pending Qty | O8: Pending Value | P8: Status | Q8: Entry By | R8: Entry At | AA8: =IFERROR( IF(ISNUMBER(C8),C8,DATE(VALUE(RIGHT(C8,4)),VALUE(MID(SUBSTITUTE(C8,"/","-"),FIND("-",SUBSTITUTE(C8,"/","-"))+1,FIND("-",SUBSTITUTE(C8,"/","-"),FIND("-",SUBSTITUTE(C8,"/","-"))+1)-FIND("-",SUBSTITUTE(C8,"/","-"))-1)),VALUE(LEFT(SUBSTITUTE(C8,"/","-"),FIND("-",SUBSTITUTE(C8,"/","-"))-1)))), DATE(1995,1,1) ) -> 34700
A9: 1 | B9: 2118 | C9: 21-06-2026 | E9: FAN | F9: MEP | G9: 3101010016 | H9: Super Wire (SWG 33) / 0.253mm | I9: KG | J9: 14000 | K9: 26874577 | M9: 0 | N9: 14000 | O9: 26874577 | P9: PENDING | Q9: 144 | R9: 46196.36 | AA9: =IFERROR( IF(ISNUMBER(C9),C9,DATE(VALUE(RIGHT(C9,4)),VALUE(MID(SUBSTITUTE(C9,"/","-"),FIND("-",SUBSTITUTE(C9,"/","-"))+1,FIND("-",SUBSTITUTE(C9,"/","-"),FIND("-",SUBSTITUTE(C9,"/","-"))+1)-FIND("-",SUBSTITUTE(C9,"/","-"))-1)),VALUE(LEFT(SUBSTITUTE(C9,"/","-"),FIND("-",SUBSTITUTE(C9,"/","-"))-1)))), DATE(1995,1,1) ) -> 46194
A10: 2 | B10: 2209 | C10: 22-07-2026 | E10: FAN | F10: MEP | G10: 3101010016 | H10: Super Wire (SWG 33) / 0.253mm | I10: KG | J10: 11000 | K10: 21115739 | M10: 0 | N10: 11000 | O10: 21115739 | P10: PENDING | Q10: 144 | R10: 46228.357 | AA10: =IFERROR( IF(ISNUMBER(C10),C10,DATE(VALUE(RIGHT(C10,4)),VALUE(MID(SUBSTITUTE(C10,"/","-"),FIND("-",SUBSTITUTE(C10,"/","-"))+1,FIND("-",SUBSTITUTE(C10,"/","-"),FIND("-",SUBSTITUTE(C10,"/","-"))+1)-FIND("-",SUBSTITUTE(C10,"/","-"))-1)),VALUE(LEFT(SUBSTITUTE(C10,"/","-"),FIND("-",SUBSTITUTE(C10,"/","-"))-1)))), DATE(1995,1,1) ) -> 46225
A11: 3 | B11: 2288 | C11: 22-08-2026 | E11: FAN | F11: MEP | G11: 3101010016 | H11: Super Wire (SWG 33) / 0.253mm | I11: KG | J11: 8000 | K11: 15356901 | M11: 0 | N11: 8000 | O11: 15356901 | P11: CHECKED | Q11: 144 | R11: 46260.692 | AA11: =IFERROR( IF(ISNUMBER(C11),C11,DATE(VALUE(RIGHT(C11,4)),VALUE(MID(SUBSTITUTE(C11,"/","-"),FIND("-",SUBSTITUTE(C11,"/","-"))+1,FIND("-",SUBSTITUTE(C11,"/","-"),FIND("-",SUBSTITUTE(C11,"/","-"))+1)-FIND("-",SUBSTITUTE(C11,"/","-"))-1)),VALUE(LEFT(SUBSTITUTE(C11,"/","-"),FIND("-",SUBSTITUTE(C11,"/","-"))-1)))), DATE(1995,1,1) ) -> 46256
A12: 4 | B12: 2209 | C12: 22-07-2026 | E12: FAN | F12: MEP | G12: 3101010017 | H12: Super Wire (SWG 34) / 0.233mm | I12: KG | J12: 1500 | K12: 3046328.5 | M12: 0 | N12: 1500 | O12: 3046328.5 | P12: PENDING | Q12: 144 | R12: 46228.357 | AA12: =IFERROR( IF(ISNUMBER(C12),C12,DATE(VALUE(RIGHT(C12,4)),VALUE(MID(SUBSTITUTE(C12,"/","-"),FIND("-",SUBSTITUTE(C12,"/","-"))+1,FIND("-",SUBSTITUTE(C12,"/","-"),FIND("-",SUBSTITUTE(C12,"/","-"))+1)-FIND("-",SUBSTITUTE(C12,"/","-"))-1)),VALUE(LEFT(SUBSTITUTE(C12,"/","-"),FIND("-",SUBSTITUTE(C12,"/","-"))-1)))), DATE(1995,1,1) ) -> 46225
A13: 5 | B13: 2288 | C13: 22-08-2026 | E13: FAN | F13: MEP | G13: 3101010017 | H13: Super Wire (SWG 34) / 0.233mm | I13: KG | J13: 3000 | K13: 6092657.1 | M13: 0 | N13: 3000 | O13: 6092657.1 | P13: CHECKED | Q13: 144 | R13: 46260.692 | AA13: =IFERROR( IF(ISNUMBER(C13),C13,DATE(VALUE(RIGHT(C13,4)),VALUE(MID(SUBSTITUTE(C13,"/","-"),FIND("-",SUBSTITUTE(C13,"/","-"))+1,FIND("-",SUBSTITUTE(C13,"/","-"),FIND("-",SUBSTITUTE(C13,"/","-"))+1)-FIND("-",SUBSTITUTE(C13,"/","-"))-1)),VALUE(LEFT(SUBSTITUTE(C13,"/","-"),FIND("-",SUBSTITUTE(C13,"/","-"))-1)))), DATE(1995,1,1) ) -> 46256
A14: 6 | B14: 2118 | C14: 21-06-2026 | E14: FAN | F14: MEP | G14: 3101010018 | H14: Super Wire (SWG 35) / 0.213mm | I14: KG | J14: 2000 | K14: 2486567.2 | M14: 0 | N14: 2000 | O14: 2486567.2 | P14: PENDING | Q14: 144 | R14: 46196.36 | AA14: =IFERROR( IF(ISNUMBER(C14),C14,DATE(VALUE(RIGHT(C14,4)),VALUE(MID(SUBSTITUTE(C14,"/","-"),FIND("-",SUBSTITUTE(C14,"/","-"))+1,FIND("-",SUBSTITUTE(C14,"/","-"),FIND("-",SUBSTITUTE(C14,"/","-"))+1)-FIND("-",SUBSTITUTE(C14,"/","-"))-1)),VALUE(LEFT(SUBSTITUTE(C14,"/","-"),FIND("-",SUBSTITUTE(C14,"/","-"))-1)))), DATE(1995,1,1) ) -> 46194
A15: 7 | B15: 2209 | C15: 22-07-2026 | E15: FAN | F15: MEP | G15: 3101010018 | H15: Super Wire (SWG 35) / 0.213mm | I15: KG | J15: 2500 | K15: 3108209 | M15: 0 | N15: 2500 | O15: 3108209 | P15: PENDING | Q15: 144 | R15: 46228.357 | AA15: =IFERROR( IF(ISNUMBER(C15),C15,DATE(VALUE(RIGHT(C15,4)),VALUE(MID(SUBSTITUTE(C15,"/","-"),FIND("-",SUBSTITUTE(C15,"/","-"))+1,FIND("-",SUBSTITUTE(C15,"/","-"),FIND("-",SUBSTITUTE(C15,"/","-"))+1)-FIND("-",SUBSTITUTE(C15,"/","-"))-1)),VALUE(LEFT(SUBSTITUTE(C15,"/","-"),FIND("-",SUBSTITUTE(C15,"/","-"))-1)))), DATE(1995,1,1) ) -> 46225
A16: 8 | B16: 2288 | C16: 22-08-2026 | E16: FAN | F16: MEP | G16: 3101010018 | H16: Super Wire (SWG 35) / 0.213mm | I16: KG | J16: 3000 | K16: 3729850.8 | M16: 0 | N16: 3000 | O16: 3729850.8 | P16: CHECKED | Q16: 144 | R16: 46260.692 | AA16: =IFERROR( IF(ISNUMBER(C16),C16,DATE(VALUE(RIGHT(C16,4)),VALUE(MID(SUBSTITUTE(C16,"/","-"),FIND("-",SUBSTITUTE(C16,"/","-"))+1,FIND("-",SUBSTITUTE(C16,"/","-"),FIND("-",SUBSTITUTE(C16,"/","-"))+1)-FIND("-",SUBSTITUTE(C16,"/","-"))-1)),VALUE(LEFT(SUBSTITUTE(C16,"/","-"),FIND("-",SUBSTITUTE(C16,"/","-"))-1)))), DATE(1995,1,1) ) -> 46256
A17: 9 | B17: 2116 | C17: 21-06-2026 | D17: 1526714869 | E17: FAN | F17: MEP | G17: 3101010070 | H17: Ms Washer 3/16 (1910/kg) | I17: KG | J17: 24 | K17: 8639.55 | L17: 18.8 | M17: 6767.65 | N17: 5.2 | O17: 1871.9 | P17: PENDING | Q17: 144 | R17: 46196.359 | AA17: =IFERROR( IF(ISNUMBER(C17),C17,DATE(VALUE(RIGHT(C17,4)),VALUE(MID(SUBSTITUTE(C17,"/","-"),FIND("-",SUBSTITUTE(C17,"/","-"))+1,FIND("-",SUBSTITUTE(C17,"/","-"),FIND("-",SUBSTITUTE(C17,"/","-"))+1)-FIND("-",SUBSTITUTE(C17,"/","-"))-1)),VALUE(LEFT(SUBSTITUTE(C17,"/","-"),FIND("-",SUBSTITUTE(C17,"/","-"))-1)))), DATE(1995,1,1) ) -> 46194
A18: 10 | B18: 2203 | C18: 22-07-2026 | D18: 15788 | E18: FAN | F18: MEP | G18: 3101010070 | H18: Ms Washer 3/16 (1910/kg) | I18: KG | J18: 22 | K18: 7919.59 | L18: 10.4 | M18: 3743.8 | N18: 11.6 | O18: 4175.78 | P18: PENDING | Q18: 144 | R18: 46228.355 | AA18: =IFERROR( IF(ISNUMBER(C18),C18,DATE(VALUE(RIGHT(C18,4)),VALUE(MID(SUBSTITUTE(C18,"/","-"),FIND("-",SUBSTITUTE(C18,"/","-"))+1,FIND("-",SUBSTITUTE(C18,"/","-"),FIND("-",SUBSTITUTE(C18,"/","-"))+1)-FIND("-",SUBSTITUTE(C18,"/","-"))-1)),VALUE(LEFT(SUBSTITUTE(C18,"/","-"),FIND("-",SUBSTITUTE(C18,"/","-"))-1)))), DATE(1995,1,1) ) -> 46225
A19: 11 | B19: 2287 | C19: 22-08-2026 | E19: FAN | F19: MEP | G19: 3101010070 | H19: Ms Washer 3/16 (1910/kg) | I19: KG | J19: 15 | K19: 5399.72 | M19: 0 | N19: 15 | O19: 5399.72 | P19: CHECKED | Q19: 144 | R19: 46260.691 | AA19: =IFERROR( IF(ISNUMBER(C19),C19,DATE(VALUE(RIGHT(C19,4)),VALUE(MID(SUBSTITUTE(C19,"/","-"),FIND("-",SUBSTITUTE(C19,"/","-"))+1,FIND("-",SUBSTITUTE(C19,"/","-"),FIND("-",SUBSTITUTE(C19,"/","-"))+1)-FIND("-",SUBSTITUTE(C19,"/","-"))-1)),VALUE(LEFT(SUBSTITUTE(C19,"/","-"),FIND("-",SUBSTITUTE(C19,"/","-"))-1)))), DATE(1995,1,1) ) -> 46256
A20: 12 | B20: 2116 | C20: 21-06-2026 | D20: 1.4789147e+99 | E20: FAN | F20: MEP | G20: 3101010071 | H20: Down Pipe Bolt 8mm x 1.5```` (50/kg) | I20: Pcs | J20: 130200 | K20: 387203.48 | L20: 91802 | M20: 273011.16 | N20: 38398 | O20: 114192.31 | P20: PENDING | Q20: 144 | R20: 46196.359 | AA20: =IFERROR( IF(ISNUMBER(C20),C20,DATE(VALUE(RIGHT(C20,4)),VALUE(MID(SUBSTITUTE(C20,"/","-"),FIND("-",SUBSTITUTE(C20,"/","-"))+1,FIND("-",SUBSTITUTE(C20,"/","-"),FIND("-",SUBSTITUTE(C20,"/","-"))+1)-FIND("-",SUBSTITUTE(C20,"/","-"))-1)),VALUE(LEFT(SUBSTITUTE(C20,"/","-"),FIND("-",SUBSTITUTE(C20,"/","-"))-1)))), DATE(1995,1,1) ) -> 46194
